# 36-异常处理(错误和异常)

标签（空格分隔）： python

---

## 1 错误和异常的区别

 - 异常可以通过代码进行修复，而错误不行

## 2 常见的系统异常
 - 除零异常：ZeroDivisionError
 - 名称异常：NameError
 - 类型异常：TypeError
 - 索引异常：IndexError

```python
lis = [1, 2]
lis[2]
```
 - 键异常：KeyError
```python
dic = {"name":"fkm", "age":22}
dic["aaa"]
```
 - 值异常：ValueError
 - 属性异常：AttributeError
 - 迭代器异常：StopIteration
 - 系统异常类继承树： 

## 3 解决异常
### 3.1 预防

 - 添加容错代码
 - 弊端：容错代码不属于主业务逻辑，过多容错代码会造成代码逻辑混乱，业务线流程不清晰
```python
# 抛异常代码
def devide(x, y):
    return x / y

# 容错处理
def devide(x, y):
    if y != 0:
        return x / y
    print(“除数不能为0”)
    return 0
```

### 3.2 解决
#### 3.2.1 try except 方案

 1. 简单解决
```python
try:
    print(name)
except NameError:
    print("名称有问题，请检查")

print(123123)

>>>>打印结果
名称有问题，请检查
123123
```
 2. 使用 try except 完整结构处理
    - 简单指定异常捕获
```python
try:
    1 / 0
except ZeroDivisionError:
    print("ZeroDivisionError")


print("程序继续运行到最后")

>>>>打印结果
ZeroDivisionError
程序继续运行到最后
```

 - try 语句没有捕获到异常，执行顺序为： try 代码段 -> else代码段 -> finally代码段
```python

try:
    print("无异常")
except ZeroDivisionError:
    print("except - ZeroDivisionError")
else:
    print("else - 没有异常时执行")
finally:
    print("finally - 有无异常都会执行")


print("程序继续运行到最后")

>>>>打印结果
无异常
else - 没有异常时执行
finally - 有无异常都会执行
程序继续运行到最后
```

 - try 有 捕获到异常，执行顺序为： try 代码段 -> except区代码段 -> finally代码段
```python
try:
    1 / 0
except ZeroDivisionError:
    print("except - ZeroDivisionError")
else:
    print("else - 没有异常时执行")
finally:
    print("finally - 有无异常都会执行")


print("程序继续运行到最后")

>>>>打印结果
except - ZeroDivisionError
finally - 有无异常都会执行
程序继续运行到最后
```

 - try块中，即使有多个异常，都只会捕获首个异常
```python
try:
    1 / 0 # 首个被处理异常
    print(name) # 后面异常不处理
except ZeroDivisionError:
    print("except - ZeroDivisionError")
except NameError:
    print("except - NameError")
else:
    print("else - 没有异常时执行")
finally:
    print("finally - 有无异常都会执行")


print("程序继续运行到最后")

>>>>打印结果
except - ZeroDivisionError
finally - 有无异常都会执行
程序继续运行到最后
```

 - as获取对应的异常的类型值
```python
try:
    1 / 0
except ZeroDivisionError:
    print("ZeroDivisionError")


print("程序继续运行到最后")

>>>>打印结果
ZeroDivisionError
程序继续运行到最后
```

```python
try:
    # 1 / 0 # 首个被处理异常
    print(name)
except ZeroDivisionError as zde:
    print("except - ZeroDivisionError", zde)
except NameError as ne:
    print("except - NameError", ne)
else:
    print("else - 没有异常时执行")
finally:
    print("finally - 有无异常都会执行")


print("程序继续运行到最后")

>>>>打印结果
except - NameError name 'name' is not defined
finally - 有无异常都会执行
程序继续运行到最后
```

 - 合并异常处理
```python
try:
    # 1 / 0 # 首个被处理异常
    print(name)
except (ZeroDivisionError, NameError) as zde:
    print("except - ZeroDivisionError", zde)
# except NameError as ne:
#     print("except - NameError", ne)
else:
    print("else - 没有异常时执行")
finally:
    print("finally - 有无异常都会执行")


print("程序继续运行到最后")

>>>>打印结果
except - ZeroDivisionError name 'name' is not defined
finally - 有无异常都会执行
程序继续运行到最后
```

 - 如果异常名称不确定，但又想捕获，except 中填入异常类型为 Exception 即可(含多态的概念，因为 Exception 是内置异常的父类)
```python
 try:
    # 1 / 0 # 首个被处理异常
    print(name)
except Exception as ex:
    print("except - Exception", ex)
else:
    print("else - 没有异常时执行")
finally:
    print("finally - 有无异常都会执行")


print("程序继续运行到最后")

>>>>打印结果
except - Exception name 'name' is not defined
finally - 有无异常都会执行
程序继续运行到最后
```

#### 3.2.2 with 语句方案
 1. 作用 
适用于执行某段代码 A 之前，进行预处理，执行代码 A结束后，进行清理操作不管出现了什么异常，最终都要执行一些清理操作

 2. 语法 
 ```python
with context_expression [as target(s)]:
    with-body
 ```

 3. 执行流程

----------

#### 3.2.3 调试

 1. 断言
    ```python
    def foo(s):
        n = int(s)
        assert n != 0, 'n is zero!'
        return 10 / n
    
    def main():
        foo('0')
    ```
assert的意思是，表达式n != 0应该是True,启动Python解释器时可以用-O(大写字母‘O’)参数来关闭assert：
    ```python
    $ python -O err.py
    Traceback (most recent call last):
      ...
    ZeroDivisionError: division by zero
    ```
   
 2. logging
    ```python
    import logging
    
    s = '0'
    n = int(s)
    logging.info('n = %d' % n)
    print(10 / n)
    # logging.info()就可以输出一段文本。运行，发现除了ZeroDivisionError，没有任何信息在，import logging之后添加一行配置
    import logging
    logging.basicConfig(level=logging.INFO)
    
    > INFO:root:n = 0
    > Traceback (most recent call last):
    >   File "med.py", line 7, in <module>
    >     print(10 / n)
    > ZeroDivisionError: division by zero
    ```

 3. pdb
 让程序以单步方式运行，可以随时查看运行状态
    ```python
        python -m pdb err.py
    ```
 以参数-m pdb启动后，pdb定位到下一步要执行的代码-> s = '0'。输入命令l来查看代码：

        (Pdb) l
          1     # err.py
          2  -> s = '0'
          3     n = int(s)
          4     print(10 / n)

  输入命令n可以单步执行代码：

        (Pdb) n
        > /Users/michael/Github/learn-python3/samples/debug/err.py(3)<module>()
        -> n = int(s)
        (Pdb) n
        > /Users/michael/Github/learn-python3/samples/debug/err.py(4)<module>()
        -> print(10 / n)

  任何时候都可以输入命令p 变量名来查看变量

        (Pdb) p s
        '0'
        (Pdb) p n
        0

 输入命令q结束调试，退出程序：

        (Pdb) q

 4. pdb.set_trace()

    只需要import pdb，然后，在可能出错的地方放一个pdb.set_trace()，就可以设置一个断点：

        # err.py
        import pdb
        
        s = '0'
        n = int(s)
        pdb.set_trace() # 运行到这里会自动暂停
        print(10 / n)

    运行代码，程序会自动在pdb.set_trace()暂停并进入pdb调试环境，可以用命令p查看变量，或者用命令c继续运行：
   
        $ python err.py 
        > /Users/michael/Github/learn-python3/samples/debug/err.py(7)<module>()
        -> print(10 / n)
        (Pdb) p n
        0
        (Pdb) c
        Traceback (most recent call last):
          File "err.py", line 7, in <module>
            print(10 / n)
        ZeroDivisionError: division by zero
